<?xml version="1.0" encoding="utf-8"?>
<!-- =================================================================================== -->
<!-- |    This document was autogenerated by xacro from arm2urdf.xacro                 | -->
<!-- |    EDITING THIS FILE BY HAND IS NOT RECOMMENDED                                 | -->
<!-- =================================================================================== -->
<robot name="WIDOWXL">
  <material name="silver_default">
    <color rgba="0.700 0.700 0.700 1.000"/>
  </material>
  <material name="black">
    <color rgba="0.0 0.0 0.0 1.000"/>
  </material>
  <transmission name="Rev36_tran">
    <type>transmission_interface/SimpleTransmission</type>
    <joint name="joint_1">
      <hardwareInterface>hardware_interface/EffortJointInterface</hardwareInterface>
    </joint>
    <actuator name="Rev36_actr">
      <hardwareInterface>hardware_interface/EffortJointInterface</hardwareInterface>
      <mechanicalReduction>1</mechanicalReduction>
    </actuator>
  </transmission>
  <transmission name="Rev38_tran">
    <type>transmission_interface/SimpleTransmission</type>
    <joint name="joint_2">
      <hardwareInterface>hardware_interface/EffortJointInterface</hardwareInterface>
    </joint>
    <actuator name="Rev38_actr">
      <hardwareInterface>hardware_interface/EffortJointInterface</hardwareInterface>
      <mechanicalReduction>1</mechanicalReduction>
    </actuator>
  </transmission>
  <transmission name="Rev39_tran">
    <type>transmission_interface/SimpleTransmission</type>
    <joint name="joint_3">
      <hardwareInterface>hardware_interface/EffortJointInterface</hardwareInterface>
    </joint>
    <actuator name="Rev39_actr">
      <hardwareInterface>hardware_interface/EffortJointInterface</hardwareInterface>
      <mechanicalReduction>1</mechanicalReduction>
    </actuator>
  </transmission>
  <transmission name="Rev40_tran">
    <type>transmission_interface/SimpleTransmission</type>
    <joint name="joint_4">
      <hardwareInterface>hardware_interface/EffortJointInterface</hardwareInterface>
    </joint>
    <actuator name="Rev40_actr">
      <hardwareInterface>hardware_interface/EffortJointInterface</hardwareInterface>
      <mechanicalReduction>1</mechanicalReduction>
    </actuator>
  </transmission>
  <transmission name="Rev41_tran">
    <type>transmission_interface/SimpleTransmission</type>
    <joint name="joint_5">
      <hardwareInterface>hardware_interface/EffortJointInterface</hardwareInterface>
    </joint>
    <actuator name="Rev41_actr">
      <hardwareInterface>hardware_interface/EffortJointInterface</hardwareInterface>
      <mechanicalReduction>1</mechanicalReduction>
    </actuator>
  </transmission>
  <transmission name="Slider44_tran">
    <type>transmission_interface/SimpleTransmission</type>
    <joint name="gripper_prismatic_joint_1">
      <hardwareInterface>hardware_interface/EffortJointInterface</hardwareInterface>
    </joint>
    <actuator name="Slider44_actr">
      <hardwareInterface>hardware_interface/EffortJointInterface</hardwareInterface>
      <mechanicalReduction>1</mechanicalReduction>
    </actuator>
  </transmission>
  <transmission name="Slider45_tran">
    <type>transmission_interface/SimpleTransmission</type>
    <joint name="gripper_prismatic_joint_2">
      <hardwareInterface>hardware_interface/EffortJointInterface</hardwareInterface>
    </joint>
    <actuator name="Slider45_actr">
      <hardwareInterface>hardware_interface/EffortJointInterface</hardwareInterface>
      <mechanicalReduction>1</mechanicalReduction>
    </actuator>
  </transmission>
  <gazebo>
    <plugin filename="libgazebo_ros_control.so" name="gazebo_ros_control">
      <robotNamespace>/WIDOWXL</robotNamespace>
    </plugin>
  </gazebo>
  <gazebo reference="base_link">
    <material>Gazebo/Silver</material>
    <mu1>0.2</mu1>
    <mu2>0.2</mu2>
    <selfCollide>true</selfCollide>
  </gazebo>
  <gazebo reference="shoulder_link">
    <material>Gazebo/Silver</material>
    <mu1>0.2</mu1>
    <mu2>0.2</mu2>
    <selfCollide>true</selfCollide>
  </gazebo>
  <gazebo reference="biceps_link">
    <material>Gazebo/Silver</material>
    <mu1>0.2</mu1>
    <mu2>0.2</mu2>
    <selfCollide>true</selfCollide>
  </gazebo>
  <gazebo reference="forearm_link">
    <material>Gazebo/Silver</material>
    <mu1>0.2</mu1>
    <mu2>0.2</mu2>
    <selfCollide>true</selfCollide>
  </gazebo>
  <gazebo reference="wrist_1_link">
    <material>Gazebo/Silver</material>
    <mu1>0.2</mu1>
    <mu2>0.2</mu2>
    <selfCollide>true</selfCollide>
  </gazebo>
  <gazebo reference="wrist_2_link">
    <material>Gazebo/Silver</material>
    <mu1>0.2</mu1>
    <mu2>0.2</mu2>
    <selfCollide>true</selfCollide>
  </gazebo>
  <gazebo reference="gripper_rail_link">
    <material>Gazebo/Silver</material>
    <mu1>0.2</mu1>
    <mu2>0.2</mu2>
    <selfCollide>true</selfCollide>
  </gazebo>
  <gazebo reference="gripper_right_link">
    <material>Gazebo/Silver</material>
    <mu1>0.2</mu1>
    <mu2>0.2</mu2>
    <selfCollide>true</selfCollide>
  </gazebo>
  <gazebo reference="gripper_left_link">
    <material>Gazebo/Silver</material>
    <mu1>0.2</mu1>
    <mu2>0.2</mu2>
    <selfCollide>true</selfCollide>
  </gazebo>
  <!--xacro:include filename="$(find realsense2_description)/urdf/_d435.urdf.xacro" /-->
  <!--link name="base_world">

</link-->
  <!--xacro:sensor_d435 name="camera" topics_ns="camera" parent="wrist_2_link" publish_pointcloud="true">
  <origin xyz="0.01 0 -0.02" rpy="0 1.5708 0" />
</xacro:sensor_d435-->
  <link name="base_link">
    <inertial>
      <origin rpy="0 0 0" xyz="0 0 0"/>
      <mass value="10"/>
      <inertia ixx="0.0377" ixy="-0.0" ixz="0.0" iyy="0.06" iyz="0" izz="0.0376"/>
    </inertial>
    <visual>
      <origin rpy="0 0 0" xyz="0 0 0"/>
      <geometry>
        <mesh filename="package://arm/meshes/base_link.stl" scale="0.001 0.001 0.001"/>
      </geometry>
      <material name="black"/>
    </visual>
    <collision>
      <origin rpy="0 0 0" xyz="0 0 0"/>
      <geometry>
        <mesh filename="package://arm/meshes/base_link.stl" scale="0.001 0.001 0.001"/>
      </geometry>
    </collision>
  </link>
  <link name="shoulder_link">
    <inertial>
      <origin rpy="0 0 0" xyz="0 0 -0.05"/>
      <mass value="0.1569876561513581"/>
      <inertia ixx="8.4e-05" ixy="0.0" ixz="-0.0" iyy="0.000167" iyz="-0.0" izz="9.5e-05"/>
    </inertial>
    <visual>
      <origin rpy="0 0 0" xyz="0 0 -0.05"/>
      <geometry>
        <mesh filename="package://arm/meshes/shoulder_link__4__1.stl" scale="0.001 0.001 0.001"/>
      </geometry>
      <material name="black"/>
    </visual>
    <collision>
      <origin rpy="0 0 0" xyz="0 0 -0.05"/>
      <geometry>
        <mesh filename="package://arm/meshes/shoulder_link__4__1.stl" scale="0.001 0.001 0.001"/>
      </geometry>
    </collision>
  </link>
  <link name="biceps_link">
    <inertial>
      <origin rpy="0 0 0" xyz="0 0 -0.087"/>
      <mass value="0.1569876561513581"/>
      <inertia ixx="0.002465" ixy="-3e-06" ixz="3e-06" iyy="0.000388" iyz="-0.000506" izz="0.002305"/>
    </inertial>
    <visual>
      <origin rpy="0 0 0" xyz="0 0 -0.087"/>
      <geometry>
        <mesh filename="package://arm/meshes/biceps_link_1.stl" scale="0.001 0.001 0.001"/>
      </geometry>
      <material name="black"/>
    </visual>
    <collision>
      <origin rpy="0 0 0" xyz="0 0 -0.087"/>
      <geometry>
        <mesh filename="package://arm/meshes/biceps_link_1.stl" scale="0.001 0.001 0.001"/>
      </geometry>
    </collision>
  </link>
  <link name="forearm_link">
    <inertial>
      <origin rpy="0 0 0" xyz="-0.05 0 -0.232"/>
      <mass value="0.1569876561513581"/>
      <inertia ixx="0.000327" ixy="-0.0" ixz="4e-06" iyy="0.000357" iyz="0.0" izz="7.5e-05"/>
    </inertial>
    <visual>
      <origin rpy="0 0 0" xyz="-0.05 0 -0.232"/>
      <geometry>
        <mesh filename="package://arm/meshes/forearm_link_1.stl" scale="0.001 0.001 0.001"/>
      </geometry>
      <material name="black"/>
    </visual>
    <collision>
      <origin rpy="0 0 0" xyz="-0.05 0 -0.232"/>
      <geometry>
        <mesh filename="package://arm/meshes/forearm_link_1.stl" scale="0.001 0.001 0.001"/>
      </geometry>
    </collision>
  </link>
  <link name="wrist_1_link">
    <inertial>
      <origin rpy="0 0 0" xyz="-0.2 0 -0.232"/>
      <mass value="0.14997568515174237"/>
      <inertia ixx="6.4e-05" ixy="-0.0" ixz="-0.0" iyy="5.2e-05" iyz="-9e-06" izz="4.6e-05"/>
    </inertial>
    <visual>
      <origin rpy="0 0 0" xyz="-0.2 0 -0.232"/>
      <geometry>
        <mesh filename="package://arm/meshes/wrist_1_1.stl" scale="0.001 0.001 0.001"/>
      </geometry>
      <material name="black"/>
    </visual>
    <collision>
      <origin rpy="0 0 0" xyz="-0.2 0 -0.232"/>
      <geometry>
        <mesh filename="package://arm/meshes/wrist_1_1.stl" scale="0.001 0.001 0.001"/>
      </geometry>
    </collision>
  </link>
  <link name="wrist_2_link">
    <inertial>
      <origin rpy="0 0 0" xyz="-0.28 0.0 -0.232"/>
      <mass value="0.12757912716999015"/>
      <inertia ixx="4.1e-05" ixy="-0.0" ixz="-0.0" iyy="2.4e-05" iyz="-1e-06" izz="3.2e-05"/>
    </inertial>
    <visual>
      <origin rpy="0 0 0" xyz="-0.28 0.0 -0.232"/>
      <geometry>
        <mesh filename="package://arm/meshes/wrist_2_1.stl" scale="0.001 0.001 0.001"/>
      </geometry>
      <material name="black"/>
    </visual>
    <collision>
      <origin rpy="0 0 0" xyz="-0.28 0.0 -0.232"/>
      <geometry>
        <mesh filename="package://arm/meshes/wrist_2_1.stl" scale="0.001 0.001 0.001"/>
      </geometry>
    </collision>
  </link>
  <link name="gripper_rail_link">
    <inertial>
      <origin rpy="0 0 0" xyz="-0.318 0 -0.232"/>
      <mass value="0.02867149681670596"/>
      <inertia ixx="4e-06" ixy="-0.0" ixz="0.0" iyy="2.8e-05" iyz="0.0" izz="2.6e-05"/>
    </inertial>
    <visual>
      <origin rpy="0 0 0" xyz="-0.318 0 -0.232"/>
      <geometry>
        <mesh filename="package://arm/meshes/rail_fing_supp_1.stl" scale="0.001 0.001 0.001"/>
      </geometry>
      <material name="silver_default"/>
    </visual>
    <collision>
      <origin rpy="0 0 0" xyz="-0.318 0 -0.232"/>
      <geometry>
        <mesh filename="package://arm/meshes/rail_fing_supp_1.stl" scale="0.001 0.001 0.001"/>
      </geometry>
    </collision>
  </link>
  <link name="gripper_left_link">
    <inertial>
      <origin rpy="0 0 0" xyz="-0.341 -0.023 -0.232"/>
      <mass value="0.009"/>
      <inertia ixx="3e-06" ixy="0.0" ixz="0.0" iyy="3e-06" iyz="0.0" izz="1e-06"/>
    </inertial>
    <visual>
      <origin rpy="0 0 0" xyz="-0.341 -0.023 -0.232"/>
      <geometry>
        <mesh filename="package://arm/meshes/finger.stl" scale="0.001 0.001 0.001"/>
      </geometry>
      <material name="black"/>
    </visual>
    <collision>
      <origin rpy="0 0 0" xyz="-0.341 -0.023 -0.232"/>
      <geometry>
        <mesh filename="package://arm/meshes/finger.stl" scale="0.001 0.001 0.001"/>
      </geometry>
    </collision>
  </link>
  <link name="gripper_right_link">
    <inertial>
      <origin rpy="-3.1415 0 0" xyz="-0.341 0.023 0.231"/>
      <mass value="0.009"/>
      <inertia ixx="3e-06" ixy="0.0" ixz="0.0" iyy="3e-06" iyz="0.0" izz="1e-06"/>
    </inertial>
    <visual>
      <origin rpy="-3.1415 0 0" xyz="-0.341 0.023 0.231"/>
      <geometry>
        <mesh filename="package://arm/meshes/finger.stl" scale="0.001 0.001 0.001"/>
      </geometry>
      <material name="black"/>
    </visual>
    <collision>
      <origin rpy="-3.1415 0 0" xyz="-0.341 0.023 0.231"/>
      <geometry>
        <mesh filename="package://arm/meshes/finger.stl" scale="0.001 0.001 0.001"/>
      </geometry>
    </collision>
  </link>
  <!--joint name="base_joint" type="fixed">
  <parent link="base_world"/>
  <child link="base_link"/>
</joint-->
  <joint name="joint_1" type="revolute">
    <origin rpy="0 0 0" xyz="0 0 0.05"/>
    <parent link="base_link"/>
    <child link="shoulder_link"/>
    <axis xyz="0.0 0.0 1.0"/>
    <limit effort="100" lower="-3.1415" upper="3.1415" velocity="1.571"/>
  </joint>
  <joint name="joint_2" type="revolute">
    <origin rpy="0 0 0" xyz="0 0 0.04"/>
    <parent link="shoulder_link"/>
    <child link="biceps_link"/>
    <axis xyz="0.0 1.0 0.0"/>
    <limit effort="100" lower="-1.571" upper="1.571" velocity="1.571"/>
  </joint>
  <joint name="joint_3" type="revolute">
    <origin rpy="0 0 0" xyz="0.05 0 0.145"/>
    <parent link="biceps_link"/>
    <child link="forearm_link"/>
    <axis xyz="0.0 1.0 0.0"/>
    <limit effort="100" lower="-1.571" upper="1.571" velocity="1.571"/>
  </joint>
  <joint name="joint_4" type="revolute">
    <origin rpy="0 0 0" xyz="0.15 0 0"/>
    <parent link="forearm_link"/>
    <child link="wrist_1_link"/>
    <axis xyz="0.0 1.0 0.0"/>
    <limit effort="100" lower="-1.745" upper="1.745" velocity="1.571"/>
  </joint>
  <joint name="joint_5" type="revolute">
    <origin rpy="0 0 0" xyz="0.08 0 0"/>
    <parent link="wrist_1_link"/>
    <child link="wrist_2_link"/>
    <axis xyz="1.0 0.0 0.0"/>
    <limit effort="100" lower="-2.617" upper="2.617" velocity="1.571"/>
  </joint>
  <joint name="Rigid43" type="fixed">
    <origin rpy="0 0 0" xyz="0.04 0 0"/>
    <parent link="wrist_2_link"/>
    <child link="gripper_rail_link"/>
  </joint>
  <joint name="gripper_prismatic_joint_1" type="prismatic">
    <origin rpy="0 0 0" xyz="0.023 0.005 0"/>
    <parent link="gripper_rail_link"/>
    <child link="gripper_left_link"/>
    <axis xyz="0.0 1.0 0"/>
    <limit effort="100" lower="0" upper="0.024" velocity="0.5"/>
  </joint>
  <joint name="gripper_prismatic_joint_2" type="prismatic">
    <origin rpy="0 0 0" xyz="0.023 -0.005 0"/>
    <parent link="gripper_rail_link"/>
    <child link="gripper_right_link"/>
    <axis xyz="0.0 -1.0 0"/>
    <limit effort="100" lower="0" upper="0.024" velocity="0.5"/>
  </joint>
</robot>
